Workbook

Sheet Roadmap
A1: VoiceForge — Build Roadmap & Task Tracker
A2: Mark status per task · Enter actual hours · Dashboard auto-updates
B3: Task | C3: Description | D3: Est. Hours | E3: Status | F3: Actual Hrs | G3: ✓ | H3: Notes
A4: Phase 1 — Local GPU Setup (Orpheus TTS)
B5: Verify CUDA + drivers | C5: nvidia-smi → RTX 5070 Ti + CUDA 13.1 confirmed ✓ | D5: 0.5 | E5: Done | G5: =IF(E5="Done","✓","")
B6: Install PyTorch cu128 | C6: pip install torch==2.8.0+cu128 torchaudio torchvision --index-url cu128 ✓ | D6: 0.5 | E6: Done | G6: =IF(E6="Done","✓","")
B7: Verify PyTorch sees GPU | C7: python -c 'import torch; print(torch.cuda.is_available())' → True ✓ | D7: 0.5 | E7: Done | G7: =IF(E7="Done","✓","")
B8: Install LM Studio | C8: Download from lmstudio.ai, install on Windows ✓ | D8: 0.5 | E8: Done | G8: =IF(E8="Done","✓","")
B9: Download Orpheus Q4_K_M GGUF model | C9: Search orpheus-3b-0.1-ft in LM Studio, download isaiahbjork Q4_K_M (~2GB) ✓ | D9: 1 | E9: Done | G9: =IF(E9="Done","✓","")
B10: Start LM Studio local server | C10: Toggle server ON in Developer tab → port 1234 ✓ | D10: 0.5 | E10: Done | G10: =IF(E10="Done","✓","")
B11: Clone orpheus-tts-local repo | C11: git clone https://github.com/isaiahbjork/orpheus-tts-local ✓ | D11: 0.5 | E11: Done | G11: =IF(E11="Done","✓","")
B12: Install repo dependencies | C12: pip install torch numpy sounddevice requests snac ✓ | D12: 0.5 | E12: Done | G12: =IF(E12="Done","✓","")
B13: Run example.py — basic TTS test | C13: python example.py → Tara + Leo voices generated ✓ | D13: 0.5 | E13: Done | G13: =IF(E13="Done","✓","")
B14: Test emotion tags | C14: <laugh> <sigh> <whisper> <chuckle> <gasp> all working ✓ | D14: 0.5 | E14: Done | G14: =IF(E14="Done","✓","")
B15: Listen and verify audio quality | C15: Verify voices sound natural and emotions render correctly ✓ | D15: 0.5 | E15: Done | G15: =IF(E15="Done","✓","")
B16: Install faster-whisper for STT | C16: pip install faster-whisper, test transcription on wav file | D16: 1 | E16: Done | G16: =IF(E16="Done","✓","")
... B18: VRAM check | C18: nvidia-smi during generation → verify under 12GB limit | D18: 0.5 | E18: Done | G18: =IF(E18="Done","✓","")
A20: Phase 2 — FastAPI Wrapper (Orpheus Bridge)
B21: Understand LM Studio API structure | C21: LM Studio exposes OpenAI-compatible API at localhost:1234 | D21: 0.5 | E21: Done | G21: =IF(E21="Done","✓","")
B22: Install FastAPI + uvicorn | C22: pip install fastapi uvicorn python-multipart soundfile | D22: 0.5 | E22: Done | G22: =IF(E22="Done","✓","")
B23: Build /tts endpoint | C23: POST text+voice → calls LM Studio:1234 → decodes SNAC tokens → returns .wav | D23: 2.5 | E23: Done | G23: =IF(E23="Done","✓","")
B24: Integrate SNAC decoder | C24: pip install snac → decode Orpheus token output into audio waveform | D24: 1.5 | E24: Done | G24: =IF(E24="Done","✓","")
B25: Build /tts/voices endpoint | C25: GET /voices → returns list of 8 available Orpheus voices | D25: 0.5 | E25: Done | G25: =IF(E25="Done","✓","")
B26: Build /stt endpoint | C26: POST audio file → faster-whisper transcribes → returns JSON transcript | D26: 1.5 | E26: Done | G26: =IF(E26="Done","✓","")
B27: Add emotion tag validator | C27: Whitelist valid tags: laugh,sigh,whisper,chuckle,gasp,cough,groan,yawn | D27: 1 | E27: Done | G27: =IF(E27="Done","✓","")
B28: Add API key auth middleware | C28: Validate Bearer token on all routes before processing | D28: 1 | E28: Done | F28: 1 | G28: =IF(E28="Done","✓","")
B29: Add char count + credit deduction | C29: Count input chars → call Express credit API → deduct before generating | D29: 1 | E29: Done | F29: 1 | G29: =IF(E29="Done","✓","")
B30: Stream audio response to client | C30: Pipe generated wav bytes directly to response, set audio/wav header | D30: 1.5 | E30: Done | F30: 1 | G30: =IF(E30="Done","✓","")
B31: Test all endpoints via Postman | C31: TTS → STT → voices → verify auth, credits, audio quality | D31: 1.5 | E31: Done | F31: 1 | G31: =IF(E31="Done","✓","")
B32: Expose via ngrok for frontend dev | C32: ngrok http 8000 → public URL for Next.js frontend testing | D32: 0.5 | E32: Done | F32: 1 | G32: =IF(E32="Done","✓","")
B33: Write Dockerfile for production | C33: Orpheus GGUF + faster-whisper + FastAPI in one Linux image | D33: 2 | E33: Done | F33: 1 | G33: =IF(E33="Done","✓","")
B34: Test Docker image locally | C34: docker build + run → verify same behavior as local server | D34: 1 | E34: Done | F34: 1 | G34: =IF(E34="Done","✓","")
B35: Document all API routes | C35: Write endpoint docs: params, responses, error codes | D35: 1 | E35: Done | F35: 1 | G35: =IF(E35="Done","✓","")
A37: Phase 3 — Express Backend
B38: Init Node.js + Express project | C38: npm init, install express cors dotenv | D38: 0.5 | E38: Not Started | G38: =IF(E38="Done","✓","")
B39: Setup PostgreSQL + Prisma | C39: neon.tech free DB + prisma init | D39: 1.5 | E39: Not Started | G39: =IF(E39="Done","✓","")
B40: Design DB schema | C40: Users, ApiKeys, Credits, UsageLogs tables | D40: 1.5 | E40: Not Started | G40: =IF(E40="Done","✓","")
B41: Run prisma migrate | C41: Push schema to DB, verify tables created | D41: 0.5 | E41: Not Started | G41: =IF(E41="Done","✓","")
B42: Build JWT auth (register/login) | C42: POST /auth/register + /auth/login endpoints | D42: 2 | E42: Not Started | G42: =IF(E42="Done","✓","")
B43: Build API key system | C43: Generate, hash, validate API keys per user | D43: 2 | E43: Not Started | G43: =IF(E43="Done","✓","")
...

Sheet Dashboard
A2: VoiceForge — Build Dashboard
A3: Live progress tracker — update status on Roadmap sheet to refresh
B5: TOTAL TASKS | D5: COMPLETED | F5: IN PROGRESS
B6: =COUNTIF(Roadmap!E4:E89,"Done")+COUNTIF(Roadmap!E4:E89,"Not Started")+COUNTIF(Roadmap!E4:E89,"In Progress")+COUNTIF(Roadmap!E4:E89,"Blocked") | D6: =COUNTIF(Roadmap!E4:E89,"Done") | F6: =COUNTIF(Roadmap!E4:E89,"In Progress")
B7: tasks total | D7: tasks done ✓ | F7: tasks active
B9: EST. TOTAL HOURS | D9: HOURS LOGGED | F9: % COMPLETE
B10: =SUM(Roadmap!D4:D89) | D10: =SUM(Roadmap!F4:F89) | F10: =IFERROR(COUNTIF(Roadmap!E4:E89,"Done")/(COUNTIF(Roadmap!E4:E89,"Done")+COUNTIF(Roadmap!E4:E89,"Not Started")+COUNTIF(Roadmap!E4:E89,"In Progress")+COUNTIF(Roadmap!E4:E89,"Blocked")),0)
B11: hours planned | D11: actual hours | F11: completion rate
B13: Phase Progress
B14: Phase | D14: Total | E14: Done | F14: Est Hrs | G14: Progress
B15: Phase 1 — Local GPU Setup (Orpheus TTS) | D15: 14 | E15: =COUNTIF(Roadmap!E5:E18,"Done") | F15: =SUM(Roadmap!D5:D18) | G15: =IFERROR(COUNTIF(Roadmap!E5:E18,"Done")/14,0)
B16: Phase 2 — FastAPI Wrapper (Orpheus Bridge) | D16: 15 | E16: =COUNTIF(Roadmap!E21:E35,"Done") | F16: =SUM(Roadmap!D21:D35) | G16: =IFERROR(COUNTIF(Roadmap!E21:E35,"Done")/15,0)
B17: Phase 3 — Express Backend | D17: 14 | E17: =COUNTIF(Roadmap!E38:E51,"Done") | F17: =SUM(Roadmap!D38:D51) | G17: =IFERROR(COUNTIF(Roadmap!E38:E51,"Done")/14,0)
B18: Phase 4 — Next.js Frontend | D18: 11 | E18: =COUNTIF(Roadmap!E54:E64,"Done") | F18: =SUM(Roadmap!D54:D64) | G18: =IFERROR(COUNTIF(Roadmap!E54:E64,"Done")/11,0)
B19: Phase 5 — Integration & QA | D19: 8 | E19: =COUNTIF(Roadmap!E67:E74,"Done") | F19: =SUM(Roadmap!D67:D74) | G19: =IFERROR(COUNTIF(Roadmap!E67:E74,"Done")/8,0)
B20: Phase 6 — Production Deployment | D20: 11 | E20: =COUNTIF(Roadmap!E77:E87,"Done") | F20: =SUM(Roadmap!D77:D87) | G20: =IFERROR(COUNTIF(Roadmap!E77:E87,"Done")/11,0)
B21: TOTAL | D21: =SUM(D15:D20) | E21: =SUM(E15:E20) | F21: =SUM(F15:F20) | G21: =IFERROR(E21/D21,0)
B23: Monthly Cost Tracker (Serverless GPU)
B24: Service | C24: Provider | D24: Plan | E24: INR/month | F24: Notes | G24: Notes
B25: GPU Server | C25: RunPod | D25: RTX 4090 Serverless | F25: Edit ↑ based on actual usage | G25: Edit ↑ based on actual usage
B26: Express Backend | C26: Railway | D26: Hobby | E26: 400 | F26: Fixed monthly | G26: Fixed monthly
B27: Next.js Frontend | C27: Vercel | D27: Hobby | E27: 0 | F27: Free tier | G27: Free tier
B28: PostgreSQL | C28: Neon | D28: Serverless Free | E28: 0 | F28: Free up to 0.5GB | G28: Free up to 0.5GB
B29: Redis | C29: Upstash | D29: Free | E29: 0 | F29: 10k commands/day free | G29: 10k commands/day free
B30: Payments | C30: Razorpay | D30: Pay per txn | E30: 0 | F30: 2% per transaction | G30: 2% per transaction
B31: Domain | C31: Any registrar | D31: Annual | E31: 0 | F31: ~₹800/yr = ₹67/mo | G31: ~₹800/yr = ₹67/mo
B32: TOTAL (excl GPU) | E32: =SUM(E26:E31)

Sheet Schedule
A1: VoiceForge — Weekly Build Schedule
A2: Plan your weekly hours · Each cell = hours you'll work on that day · Adjust to your own pace
B4: Phase / Task | C4: Mon | D4: Tue | E4: Wed | F4: Thu | G4: Fri | H4: Sat | I4: Sun | J4: Total Hrs
B5: Phase 1 — Orpheus GPU Setup | C5: 1 | D5: 1 | E5: 1 | F5: 1 | G5: 0.5 | H5: 2 | I5: 1 | J5: =SUM(C5:I5)
B6: Phase 2 — FastAPI Wrapper | C6: 2 | D6: 2 | E6: 2 | F6: 2 | G6: 2 | H6: 3 | I6: 3 | J6: =SUM(C6:I6)
B7: Phase 3 — Express Backend | C7: 2 | D7: 2 | E7: 2 | F7: 2 | G7: 2 | H7: 3 | I7: 2 | J7: =SUM(C7:I7)
B8: Phase 4 — Next.js Frontend | C8: 2 | D8: 2 | E8: 2 | F8: 2 | G8: 2 | H8: 3 | I8: 2 | J8: =SUM(C8:I8)
B9: Phase 5 — Integration & QA | C9: 1.5 | D9: 1.5 | E9: 1.5 | F9: 1.5 | G9: 1.5 | H9: 2.5 | I9: 2 | J9: =SUM(C9:I9)
B10: Phase 6 — Deployment | C10: 1.5 | D10: 1.5 | E10: 1.5 | F10: 1.5 | G10: 1 | H10: 2 | I10: 1.5 | J10: =SUM(C10:I10)
B11: TOTAL HOURS / DAY | C11: =SUM(C5:C10) | D11: =SUM(D5:D10) | E11: =SUM(E5:E10) | F11: =SUM(F5:F10) | G11: =SUM(G5:G10) | H11: =SUM(H5:H10) | I11: =SUM(I5:I10) | J11: =SUM(J5:J10)
B13: Tips: Phase 1 is mostly complete — you already have Orpheus running with emotion tags. Phase 2 (FastAPI wrapper) is the next big task. Total ~105hrs ≈ 4-5 weeks part-time.
